Workbook

Sheet Start here
B2: XYZ Properties - CRM
B3: One spreadsheet behind all four n8n workflows. Upload to Google Drive, open as a Google Sheet, and paste its ID into each workflow's Config node.
B5: SETUP
B6: 1. Upload | C6: File > Import is not needed. Put this .xlsx in Google Drive, right-click > Open with > Google Sheets, then File > Save as Google Sheets.
B7: 2. Copy the ID | C7: From the URL: docs.google.com/spreadsheets/d/THIS-PART-HERE/edit
B8: 3. Paste it | C8: Into SHEET_ID in the Config node of RE-00, RE-04 and RE-05.
B9: 4. Fill in Projects | C9: The only tab you edit by hand. Two example rows are shaded - overwrite them with your real projects.
B10: 5. Share | C10: Share the sheet with the Google account whose credential n8n uses, as Editor.
B12: THE TABS
B13: Leads | C13: One row per buyer. Written by n8n, matched on the phone column. Do not reorder or rename columns.
B14: Projects | C14: Reference data you own. Every price, photo and brochure link the bot sends comes from here.
B15: Visits | C15: One row per booked site visit, written when a buyer taps a slot.
B16: Messages | C16: Full inbound/outbound log - what was sent, to whom, when.
B17: Dashboard | C17: Live formulas over the tabs above. Read-only.
B18: Field guide | C18: What writes each column and what a real value looks like.
B20: RULES THAT MATTER
B21: Never rename a column | C21: The workflows map to headers by name. A renamed header silently stops being written.
B22: Never reorder tabs or rename them | C22: n8n looks tabs up by name: Leads, Projects, Visits, Messages.
B23: Keep row 1 as the header | C23: n8n reads row 1 to build its column map.
B24: Yours to edit | C24: The Projects tab, plus owner and notes on Leads. Everything else is machine-written.
B25: Public image and brochure links | C25: Meta fetches them server-side. A Drive share link returns HTML, not a file, and the send fails.

Sheet Dashboard
A1: Pipeline at a glance
A2: Live counts straight from the Leads tab. Nothing to edit here - every cell is a formula.
A4: Pipeline
A5: Total leads | B5: =COUNTA(Leads!$A$2:$A$5000)
A6: New - awaiting first call | B6: =COUNTIF(Leads!$O$2:$O$5000,"New")
A7: Engaged - in conversation | B7: =COUNTIF(Leads!$O$2:$O$5000,"Engaged")
A8: Nurturing - in the follow-up sequence | B8: =COUNTIF(Leads!$O$2:$O$5000,"Nurturing")
A9: Visit scheduled | B9: =COUNTIF(Leads!$O$2:$O$5000,"Visit Scheduled")
A10: Booked | B10: =COUNTIF(Leads!$O$2:$O$5000,"Booked")
A11: Lost or dropped | B11: =COUNTIF(Leads!$O$2:$O$5000,"Lost")+COUNTIF(Leads!$O$2:$O$5000,"Dropped")
A13: Grades
A14: HOT | B14: =COUNTIF(Leads!$P$2:$P$5000,"HOT")
A15: WARM | B15: =COUNTIF(Leads!$P$2:$P$5000,"WARM")
A16: COLD | B16: =COUNTIF(Leads!$P$2:$P$5000,"COLD")
A17: JUNK - timepass, brokers, spam | B17: =COUNTIF(Leads!$P$2:$P$5000,"JUNK")
A18: Ungraded | B18: =COUNTA(Leads!$A$2:$A$5000)-COUNTIF(Leads!$P$2:$P$5000,"HOT")-COUNTIF(Leads!$P$2:$P$5000,"WARM")-COUNTIF(Leads!$P$2:$P$5000,"COLD")-COUNTIF(Leads!$P$2:$P$5000,"JUNK")
A20: Nurture and activity
A21: At the 6-follow-up cap - needs a human | B21: =COUNTIF(Leads!$Y$2:$Y$5000,">=6")
A22: Site visits booked (Visits tab) | B22: =COUNTA(Visits!$A$2:$A$5000)
A23: WhatsApp messages sent | B23: =COUNTIF(Messages!$D$2:$D$20000,"outbound")
A24: Messages received from buyers | B24: =COUNTIF(Messages!$D$2:$D$20000,"inbound")
A25: Enquiry to booking | B25: =IFERROR(B10/B5,0)
A26: Enquiry to site visit | B26: =IFERROR((B9+B10)/B5,0)
A28: By source
A29: Source | B29: Leads | C29: Hot | D29: Junk | E29: Visits | F29: Booked | G29: Conv.
A30: website | B30: =COUNTIF(Leads!$H$2:$H$5000,$A30) | C30: =COUNTIFS(Leads!$H$2:$H$5000,$A30,Leads!$P$2:$P$5000,"HOT") | D30: =COUNTIFS(Leads!$H$2:$H$5000,$A30,Leads!$P$2:$P$5000,"JUNK") | E30: =COUNTIFS(Leads!$H$2:$H$5000,$A30,Leads!$O$2:$O$5000,"Visit Scheduled") | F30: =COUNTIFS(Leads!$H$2:$H$5000,$A30,Leads!$O$2:$O$5000,"Booked") | G30: =IFERROR($F30/$B30,0)
A31: meta_ads | B31: =COUNTIF(Leads!$H$2:$H$5000,$A31) | C31: =COUNTIFS(Leads!$H$2:$H$5000,$A31,Leads!$P$2:$P$5000,"HOT") | D31: =COUNTIFS(Leads!$H$2:$H$5000,$A31,Leads!$P$2:$P$5000,"JUNK") | E31: =COUNTIFS(Leads!$H$2:$H$5000,$A31,Leads!$O$2:$O$5000,"Visit Scheduled") | F31: =COUNTIFS(Leads!$H$2:$H$5000,$A31,Leads!$O$2:$O$5000,"Booked") | G31: =IFERROR($F31/$B31,0)
A32: google_ads | B32: =COUNTIF(Leads!$H$2:$H$5000,$A32) | C32: =COUNTIFS(Leads!$H$2:$H$5000,$A32,Leads!$P$2:$P$5000,"HOT") | D32: =COUNTIFS(Leads!$H$2:$H$5000,$A32,Leads!$P$2:$P$5000,"JUNK") | E32: =COUNTIFS(Leads!$H$2:$H$5000,$A32,Leads!$O$2:$O$5000,"Visit Scheduled") | F32: =COUNTIFS(Leads!$H$2:$H$5000,$A32,Leads!$O$2:$O$5000,"Booked") | G32: =IFERROR($F32/$B32,0)
A33: 99acres | B33: =COUNTIF(Leads!$H$2:$H$5000,$A33) | C33: =COUNTIFS(Leads!$H$2:$H$5000,$A33,Leads!$P$2:$P$5000,"HOT") | D33: =COUNTIFS(Leads!$H$2:$H$5000,$A33,Leads!$P$2:$P$5000,"JUNK") | E33: =COUNTIFS(Leads!$H$2:$H$5000,$A33,Leads!$O$2:$O$5000,"Visit Scheduled") | F33: =COUNTIFS(Leads!$H$2:$H$5000,$A33,Leads!$O$2:$O$5000,"Booked") | G33: =IFERROR($F33/$B33,0)
A34: magicbricks | B34: =COUNTIF(Leads!$H$2:$H$5000,$A34) | C34: =COUNTIFS(Leads!$H$2:$H$5000,$A34,Leads!$P$2:$P$5000,"HOT") | D34: =COUNTIFS(Leads!$H$2:$H$5000,$A34,Leads!$P$2:$P$5000,"JUNK") | E34: =COUNTIFS(Leads!$H$2:$H$5000,$A34,Leads!$O$2:$O$5000,"Visit Scheduled") | F34: =COUNTIFS(Leads!$H$2:$H$5000,$A34,Leads!$O$2:$O$5000,"Booked") | G34: =IFERROR($F34/$B34,0)
A35: housing | B35: =COUNTIF(Leads!$H$2:$H$5000,$A35) | C35: =COUNTIFS(Leads!$H$2:$H$5000,$A35,Leads!$P$2:$P$5000,"HOT") | D35: =COUNTIFS(Leads!$H$2:$H$5000,$A35,Leads!$P$2:$P$5000,"JUNK") | E35: =COUNTIFS(Leads!$H$2:$H$5000,$A35,Leads!$O$2:$O$5000,"Visit Scheduled") | F35: =COUNTIFS(Leads!$H$2:$H$5000,$A35,Leads!$O$2:$O$5000,"Booked") | G35: =IFERROR($F35/$B35,0)
A36: whatsapp | B36: =COUNTIF(Leads!$H$2:$H$5000,$A36) | C36: =COUNTIFS(Leads!$H$2:$H$5000,$A36,Leads!$P$2:$P$5000,"HOT") | D36: =COUNTIFS(Leads!$H$2:$H$5000,$A36,Leads!$P$2:$P$5000,"JUNK") | E36: =COUNTIFS(Leads!$H$2:$H$5000,$A36,Leads!$O$2:$O$5000,"Visit Scheduled") | F36: =COUNTIFS(Leads!$H$2:$H$5000,$A36,Leads!$O$2:$O$5000,"Booked") | G36: =IFERROR($F36/$B36,0)
A37: walk_in | B37: =COUNTIF(Leads!$H$2:$H$5000,$A37) | C37: =COUNTIFS(Leads!$H$2:$H$5000,$A37,Leads!$P$2:$P$5000,"HOT") | D37: =COUNTIFS(Leads!$H$2:$H$5000,$A37,Leads!$P$2:$P$5000,"JUNK") | E37: =COUNTIFS(Leads!$H$2:$H$5000,$A37,Leads!$O$2:$O$5000,"Visit Scheduled") | F37: =COUNTIFS(Leads!$H$2:$H$5000,$A37,Leads!$O$2:$O$5000,"Booked") | G37: =IFERROR($F37/$B37,0)
A38: referral | B38: =COUNTIF(Leads!$H$2:$H$5000,$A38) | C38: =COUNTIFS(Leads!$H$2:$H$5000,$A38,Leads!$P$2:$P$5000,"HOT") | D38: =COUNTIFS(Leads!$H$2:$H$5000,$A38,Leads!$P$2:$P$5000,"JUNK") | E38: =COUNTIFS(Leads!$H$2:$H$5000,$A38,Leads!$O$2:$O$5000,"Visit Scheduled") | F38: =COUNTIFS(Leads!$H$2:$H$5000,$A38,Leads!$O$2:$O$5000,"Booked") | G38: =IFERROR($F38/$B38,0)
A39: Source names must match what your ad platforms and forms send in the 'source' field. Add rows here as you add channels.

Sheet Leads
A1: lead_id | B1: created_at | C1: name | D1: phone | E1: wa_id | F1: phone_e164 | G1: email | H1: source | I1: campaign | J1: project | K1: budget | L1: configuration | M1: timeline | N1: message | O1: status | P1: grade | Q1: score | R1: is_broker | S1: intent_signals | T1: risk_flags | U1: next_action | V1: ai_summary | W1: owner | X1: touch_count | Y1: followup_count | Z1: last_touch | AA1: last_inbound_at | AB1: last_followup_at | AC1: last_action | AD1: details_sent | AE1: brochure_sent | AF1: visit_event_id | AG1: visit_at | AH1: notes

Sheet Projects
A1: project_name | B1: tagline | C1: location | D1: address | E1: price_range | F1: configurations | G1: carpet_area | H1: possession | I1: rera | J1: amenities | K1: image_1 | L1: image_2 | M1: image_3 | N1: brochure_url | O1: maps_link | P1: site_office_contact
A2: XYZ Skyline Residences | B2: 2 & 3 BHK by the lake | C2: Baner, Pune | D2: Survey 21, Baner Road, Baner, Pune 411045 | E2: Rs 1.15 Cr - 1.95 Cr | F2: 2 & 3 BHK | G2: 720 - 1180 sqft | H2: Dec 2027 | I2: P52100054321 | J2: Rooftop infinity pool, clubhouse, gym, kids play area, EV charging | K2: https://cdn.example.com/skyline/tower.jpg | L2: https://cdn.example.com/skyline/livingroom.jpg | M2: https://cdn.example.com/skyline/clubhouse.jpg | N2: https://cdn.example.com/skyline/brochure.pdf | O2: https://maps.app.goo.gl/example | P2: 919999999999
A3: XYZ Green Enclave | B3: Row houses with private gardens | C3: Wagholi, Pune | D3: Plot 8, Kesnand Road, Wagholi, Pune 412207 | E3: Rs 85 L - 1.4 Cr | F3: 3 & 4 BHK | G3: 1100 - 1650 sqft | H3: Jun 2028 | I3: P52100067890 | J3: Private garden, jogging track, amphitheatre, 24x7 security | K3: https://cdn.example.com/green/rowhouse.jpg | N3: https://cdn.example.com/green/brochure.pdf | O3: https://maps.app.goo.gl/example2 | P3: 919999999999

Sheet Visits
A1: event_id | B1: lead_id | C1: name | D1: phone | E1: email | F1: project | G1: visit_start_ist | H1: visit_start_iso | I1: duration_min | J1: status | K1: booked_via | L1: sales_manager | M1: calendar_link | N1: created_at

Sheet Messages
A1: timestamp | B1: lead_id | C1: phone | D1: direction | E1: type | F1: action | G1: body | H1: wa_message_id | I1: status

Sheet Field guide
A1: Field guide
A2: Every column, what writes it, and one realistic value. This is the example row - the data tabs stay empty so nothing fake reaches a real buyer.
A4: Tab | B4: Column | C4: Written by | D4: Example value
A5: Leads
B6: lead_id | C6: RE-00 on capture | D6: L1755771000123
B7: created_at | C7: RE-00 on capture | D7: 2026-08-21T09:30:00.000Z
B8: name | C8: RE-00 from the form | D8: Rohan Kelkar
B9: phone | C9: RE-00, last 10 digits - the match key | D9: 9876543210
B10: wa_id | C10: RE-00, full international digits | D10: 919876543210
B11: phone_e164 | C11: RE-00 | D11: +919876543210
B12: email | C12: RE-00 from the form | D12: buyer@example.com
B13: source | C13: RE-00 from the form or ad platform | D13: meta_ads
B14: campaign | C14: RE-00 from the form | D14: aug-skyline-3bhk
B15: project | C15: RE-00, must match a Projects row | D15: XYZ Skyline Residences
B16: budget | C16: RE-00 from the form | D16: 1.2 Cr
B17: configuration | C17: RE-00 from the form | D17: 3BHK
... B39: notes | C39: YOU, or the last follow-up line | D39: Prefers a higher floor, east facing
A41: Projects
B42: project_name | C42: YOU - must match the project on the lead | D42: XYZ Skyline Residences
B43: tagline | C43: YOU | D43: 2 & 3 BHK by the lake
B44: location | C44: YOU | D44: Baner, Pune
B45: address | C45: YOU - shown in the visit confirmation | D45: Survey 21, Baner Road, Pune 411045
B46: price_range | C46: YOU | D46: Rs 1.15 Cr - 1.95 Cr
B47: configurations | C47: YOU | D47: 2 & 3 BHK
B48: carpet_area | C48: YOU | D48: 720 - 1180 sqft
B49: possession | C49: YOU | D49: Dec 2027
B50: rera | C50: YOU | D50: P52100054321
B51: amenities | C51: YOU | D51: Rooftop pool, clubhouse, gym, EV charging
B52: image_1 | C52: YOU - public direct link | D52: https://cdn.example.com/skyline/tower.jpg
B53: image_2 | C53: YOU - optional | D53: https://cdn.example.com/skyline/living.jpg
... B57: site_office_contact | C57: YOU | D57: 919999999999
A59: Visits
B60: event_id | C60: RE-00 - the Google Calendar event id | D60: abc123def456
B61: lead_id | C61: RE-00 | D61: L1755771000123
B62: name | C62: RE-00 | D62: Rohan Kelkar
B63: phone | C63: RE-00 | D63: +919876543210
B64: email | C64: RE-00 | D64: buyer@example.com
B65: project | C65: RE-00 | D65: XYZ Skyline Residences
B66: visit_start_ist | C66: RE-00 | D66: Saturday 23 Aug 2026, 11:00
B67: visit_start_iso | C67: RE-00 | D67: 2026-08-23T11:00:00.000+05:30
...
